<?xml version="1.0"?>
<robot name="my_robot" xmlns:xacro="http://ros.org/wiki/xacro">
  <xacro:property name="prefix" value="" />


  <!-- Base link -->
  <link name="${prefix}base_link">
    <visual>
      <geometry>
        <box size="0.118 0.039 0.05" />
      </geometry>
      <material name="grey">
        <color rgba="0.6 0.6 0.6 1.0"/>
      </material>
    </visual>
    <collision>
      <geometry>
        <box size="0.118 0.039 0.05" />
      </geometry>
    </collision>
    <inertial>
      <mass value="0.5"/>
      <origin xyz="0 0 0" rpy="0 0 0"/>
      <inertia ixx="0.001" ixy="0.0" ixz="0.0" iyy="0.001" iyz="0.0" izz="0.001"/>
    </inertial>
  </link>

  <!-- Left wheel -->
  <link name="${prefix}left_wheel_link">
    <visual>
      <geometry>
        <cylinder radius="0.024" length="0.025" />
      </geometry>
      <material name="yellow">
        <color rgba="1.0 1.0 0.0 1.0"/>
      </material>
    </visual>
    <collision>
      <geometry>
        <cylinder radius="0.024" length="0.025" />
      </geometry>
    </collision>
    <inertial>
      <mass value="0.2"/>
      <inertia ixx="0.001" ixy="0.0" ixz="0.0" iyy="0.001" iyz="0.0" izz="0.001"/>
    </inertial>
  </link>

  <!-- Right wheel -->
  <link name="${prefix}right_wheel_link">
    <visual>
      <geometry>
        <cylinder radius="0.024" length="0.025" />
      </geometry>
      <material name="yellow"/>
    </visual>
    <collision>
      <geometry>
        <cylinder radius="0.024" length="0.025" />
      </geometry>
    </collision>
    <inertial>
      <mass value="0.2"/>
      <inertia ixx="0.001" ixy="0.0" ixz="0.0" iyy="0.001" iyz="0.0" izz="0.001"/>
    </inertial>
  </link>

  <!-- Joints -->
  <joint name="${prefix}left_wheel_joint" type="continuous">
    <parent link="${prefix}base_link"/>
    <child link="${prefix}left_wheel_link"/>
    <origin xyz="0 0.038 -0.010" rpy="1.57 0 0"/>
    <axis xyz="0 0 1"/>
  </joint>

  <joint name="${prefix}right_wheel_joint" type="continuous">
    <parent link="${prefix}base_link"/>
    <child link="${prefix}right_wheel_link"/>
    <origin xyz="0 -0.038 -0.010" rpy="1.57 0 0"/>
    <axis xyz="0 0 1"/>
  </joint>

  <!-- Gazebo wheel friction settings -->
  <gazebo reference="${prefix}left_wheel_joint">
    <mu1>1.0</mu1>
    <mu2>1.0</mu2>
    <kp>100000</kp>
    <kd>1.0</kd>
  </gazebo>

  <gazebo reference="${prefix}right_wheel_joint">
    <mu1>1.0</mu1>
    <mu2>1.0</mu2>
    <kp>100000</kp>
    <kd>1.0</kd>
  </gazebo>

  <!-- Gazebo differential drive plugin -->
  <gazebo>
    <plugin name="gazebo_ros_diff_drive" filename="libgazebo_ros_diff_drive.so">
      <ros>
        <namespace>/</namespace>
      </ros>
      <update_rate>50</update_rate>
      <left_joint>${prefix}left_wheel_joint</left_joint>
      <right_joint>${prefix}right_wheel_joint</right_joint>
      <wheel_separation>0.076</wheel_separation> <!-- 0.038 + 0.038 -->
      <wheel_radius>0.024</wheel_radius>
      <command_topic>cmd_vel</command_topic>
      <odometry_topic>odom</odometry_topic>
      <odometry_frame>${prefix}odom</odometry_frame>
      <robot_base_frame>${prefix}base_link</robot_base_frame>
      <publish_tf>true</publish_tf>
    </plugin>
  </gazebo>

</robot>
